<?xml version="1.0"?>
<robot name="SimpleTank">

  <!-- Link: CHASSIS -->
  <link name="CHASSIS">
    <inertial>
      <origin xyz="0 0 0"/>
      <mass value="8.0"/>
      <inertia ixx="0.1" ixy="0" ixz="0" iyy="0.1" iyz="0" izz="0.5"/>
    </inertial>
    <visual>
      <origin xyz="0 0 0"/>
      <geometry>
        <box size="0.45 0.3 0.1"/>
      </geometry>
      <material name="BodyAppearance">
        <color rgba="0 0.6 0 1.0"/>
      </material>
    </visual>
    <collision>
      <origin xyz="0 0 0"/>
      <geometry>
        <box size="0.45 0.3 0.1"/>
      </geometry>
    </collision>
  </link>

  <!-- Joint: TURRET_Y -->
  <joint name="TURRET_Y" type="continuous">
    <parent link="CHASSIS"/>
    <child link="TURRET_Y"/>
    <origin xyz="-0.04 0 0.1"/>
    <axis xyz="0 0 -1"/>
    <limit effort="20.0" velocity="1.57"/>
  </joint>

  <!-- Link: TURRET_Y -->
  <link name="TURRET_Y">
    <inertial>
      <origin xyz="0 0 0.025"/>
      <mass value="4.0"/>
      <inertia ixx="0.1" ixy="0" ixz="0" iyy="0.1" iyz="0" izz="0.1"/>
    </inertial>
    <visual>
      <origin xyz="0 0 0"/>
      <geometry>
        <box size="0.2 0.2 0.1"/>
      </geometry>
      <material name="BodyAppearance"/>
    </visual>
    <collision>
      <origin xyz="0 0 0"/>
      <geometry>
        <box size="0.2 0.2 0.1"/>
      </geometry>
    </collision>
  </link>

  <!-- Joint: TURRET_P -->
  <joint name="TURRET_P" type="revolute">
    <parent link="TURRET_Y"/>
    <child link="TURRET_P"/>
    <origin xyz="0 0 0.05"/>
    <axis xyz="0 -1 0"/>
    <limit lower="-0.175" upper="0.785" effort="20.0" velocity="1.57"/>
  </joint>

  <!-- Link: TURRET_P -->
  <link name="TURRET_P">
    <inertial>
      <origin xyz="0 0 0"/>
      <mass value="3.0"/>
      <inertia ixx="0.1" ixy="0" ixz="0" iyy="0.1" iyz="0" izz="0.1"/>
    </inertial>
    <visual>
      <origin xyz="0 0 0" rpy="1.571 0 0"/>
      <geometry>
        <cylinder radius="0.1" length="0.1"/>
      </geometry>
      <material name="BodyAppearance"/>
    </visual>
    <collision>
      <origin xyz="0 0 0" rpy="1.571 0 0"/>
      <geometry>
        <cylinder radius="0.1" length="0.1"/>
      </geometry>
    </collision>
    <visual>
      <origin xyz="0.2 0 0" rpy="0 1.571 0"/>
      <geometry>
        <cylinder radius="0.02" length="0.2"/>
      </geometry>
      <material name="BodyAppearance"/>
    </visual>
    <collision>
      <origin xyz="0.2 0 0" rpy="0 1.571 0"/>
      <geometry>
        <cylinder radius="0.02" length="0.2"/>
      </geometry>
    </collision>
    <!-- <visual> -->
    <!--   <geometry> -->
    <!--     <cone radius="0.025" length="0.04"/> -->
    <!--   </geometry> -->
    <!--   <material name="spotlight_material"> -->
    <!--     <color rgba="1.0 1.0 0.4 1.0"/> -->
    <!--   </material> -->
    <!-- </visual> -->
    <!-- <collision> -->
    <!--   <geometry> -->
    <!--     <cone radius="0.025" length="0.04"/> -->
    <!--   </geometry> -->
    <!-- </collision> -->
    <visual>
      <origin xyz="0.1 0 0.05" rpy="0 1.571 0"/>
      <geometry>
        <cylinder radius="0.02" length="0.02"/>
      </geometry>
      <material name="camera_material">
        <color rgba="0.2 0.2 0.8 1.0"/>
      </material>
    </visual>
    <collision>
      <origin xyz="0.1 0 0.05" rpy="0 1.571 0"/>
      <geometry>
        <cylinder radius="0.02" length="0.02"/>
      </geometry>
    </collision>
  </link>

  <!-- Joint: TRACK_L -->
  <joint name="TRACK_L" type="fixed">
    <parent link="CHASSIS"/>
    <child link="TRACK_L"/>
    <origin xyz="0 0.2 0"/>
  </joint>

  <!-- Link: TRACK_L -->
  <link name="TRACK_L">
    <inertial>
      <origin xyz="0 0 0"/>
      <mass value="1.0"/>
      <inertia ixx="0.02" ixy="0" ixz="0" iyy="0.02" iyz="0" izz="0.02"/>
    </inertial>
    <!-- <visual> and <collision> for Extrusion not natively supported in URDF -->
  </link>

  <!-- Joint: TRACK_R -->
  <joint name="TRACK_R" type="fixed">
    <parent link="CHASSIS"/>
    <child link="TRACK_R"/>
    <origin xyz="0 -0.2 0"/>
  </joint>

  <!-- Link: TRACK_R -->
  <link name="TRACK_R">
    <inertial>
      <origin xyz="0 0 0"/>
      <mass value="1.0"/>
      <inertia ixx="0.02" ixy="0" ixz="0" iyy="0.02" iyz="0" izz="0.02"/>
    </inertial>
    <!-- <visual> and <collision> for Extrusion not natively supported in URDF -->
  </link>

</robot>
